Workbook
Name GC: 名称管理器!$P$2:$P$11
Name GC系列客卧式室内机: 名称管理器!$K$15:$K$33
Name GC系列室外机: 名称管理器!$M$46:$M$60
Name MDSII: 名称管理器!#REF!
Name MDSIII: 名称管理器!$R$2:$R$11
Name MDSIII系列室外机: 名称管理器!$L$46:$L$60
Name MDSII系列室外机: 名称管理器!$P$46:$P$60
Name MJV_120W_B_E01_SJ: 新风设备表!$H$17:$I$17
Name MJV_120W_E01_LHⅢ: 新风设备表!$H$5:$I$5
Name MJV_120W_E01_MZ: 名称管理器!$D$46:$S$46
Name MJV_120W_E01_SJⅡ: 新风设备表!$H$23:$I$23
Name MJV_120W_E01_TS: 新风设备表!$H$13:$I$13
Name MJV_140W_B_E01_SJ: 新风设备表!$H$18:$I$18
Name MJV_140W_E01_LHⅢ: 新风设备表!$H$6:$I$6
Name MJV_140W_E01_MZ: 名称管理器!$D$47:$S$47
Name MJV_140W_E01_SJⅡ: 新风设备表!$H$24:$I$24
Name MJV_140W_E01_TS: 新风设备表!$H$14:$I$14
Name MJV_160W_B_E01_SJ: 新风设备表!$H$19:$I$19
Name MJV_160W_E01_LHⅢ: 新风设备表!$H$7:$I$7
Name MJV_160W_E01_MZ: 名称管理器!$D$48:$S$48
Name MJV_160W_E01_SJⅡ: 新风设备表!$H$25:$I$25
Name MJV_160W_E01_TS: 新风设备表!$H$15:$I$15
Name MJV_180W_B_E01_SJ: 新风设备表!$H$20:$I$20
Name MJV_180W_E01_LHⅢ: 新风设备表!$H$8:$I$8
Name MJV_180W_E01_MZ: 名称管理器!$D$49:$S$49
Name MJV_180W_E01_SJⅡ: 新风设备表!$H$26:$I$26
Name MJV_180W_E01_TS: 新风设备表!$H$16:$I$16
Name MJV_200W_E01_LHⅢ: 新风设备表!$H$9:$I$9
Name MJV_200W_E01_MZ: 名称管理器!$D$50:$S$50
Name MJV_200W_E01_SJ: 新风设备表!$H$21:$I$21
Name MJV_200W_E01_SJⅡ: 新风设备表!$H$27:$I$27
Name MJV_200W_S_E01_LHⅢ: 新风设备表!$H$10:$I$10
Name MJV_224W_E01_LHⅢ: 新风设备表!$H$11:$I$11
Name MJV_224W_E01_MZ: 名称管理器!$D$51:$S$51
Name MJV_224W_E01_SJ: 新风设备表!$H$22:$I$22
Name MJV_224W_E01_SJⅡ: 新风设备表!$H$28:$I$28
Name MJV_224W_S_E01_LHⅢ: 新风设备表!$H$12:$I$12
Name MJV_280W_S_X8_LHII: 新风设备表!$H$3:$I$3
Name MJV_335W_S_X8_LHII: 新风设备表!$H$4:$I$4
Name SFEN_180_N1X_A: 新风设备表!$B$25
Name SFEN_180_N1X_BⅡ: 新风设备表!$C$25
Name SFEN_280_N1X_A: 新风设备表!$D$25
Name TY通用内机: 名称管理器!$O$15:$O$33
Name X空间厨房机: 名称管理器!$I$15:$I$33
Name X新风系列全热交换器: 新风设备表!$D$14:$D$17
Name 超薄轻音室内机: 名称管理器!$B$15:$B$33
Name 超薄轻音室内机Pro: 名称管理器!$C$15:$C$33
Name 厨房式室内机: 名称管理器!$L$15:$L$33
Name 厨清凉室内机: 名称管理器!$I$15:$I$33
Name 单向流新风机: 新风设备表!$C$14:$C$17
Name 对应室内机: 名称管理器!$C$2:$R$2
Name 空气梦想家: 名称管理器!#REF!
Name 空气梦想家Ⅱ: 名称管理器!$F$2:$F$11
Name 空气梦想家Ⅱ室内机: 名称管理器!$Q$15:$Q$33
Name 空气梦想家Ⅱ室外机: 名称管理器!$N$46:$N$60
Name 空气梦想家Ⅱ系列室外机: 名称管理器!$N$46:$N$60
Name 空气梦想家室内机: 名称管理器!$M$15:$M$33
Name 空气梦想家室外机: 名称管理器!#REF!
Name 空气梦想家系列室外机: 名称管理器!#REF!
Name 冷暖双舒适内机: 名称管理器!$D$15:$D$33

Sheet 空调配置选型表
A1: 美的中央空调选型配置表
A2: 项目名称： | C2: xx设计项目 | H2: 项目类型： | I2: 平层 | O2: =TODAY() -> 46139
A3: 设计区域信息 | E3: 空调设计负荷 | G3: 室内机选型 | M3: 实际房间负荷 | N3: 备注 | O3: 室外机型号 | P3: 系统连接率
A4: 楼层 | B4: 编号 | C4: 房间名称 | D4: 面积 | E4: 单位负荷 | F4: 房间负荷 | G4: 室内机形式 | H4: 室内机型号 | I4: 匹数 | J4: 数量 | K4: 制冷量 | L4: 总制冷量 | N4: 提升泵 | Q4: 机型选择 | R4: 机型选择 | S4: 机型选择
D5: m2 | E5: W/m2 | F5: kW | K5: kw | L5: kw | M5: W/m2 | Q5: 外机系列 | R5: 内机形式 | S5: 外机型号 | T5: 制冷量 | U5: 制热量 | V5: 匹数
A6: 一层 | B6: 1 | C6: 客餐厅 | D6: 55 | E6: 230 | F6: =(D6*E6)/1000 -> 12.65 | G6: =R6 -> 超薄轻音室内机Pro | H6: MJV-80T2/X-TS | I6: =VLOOKUP(H6,室内机清单!A:E,4,FALSE) -> 大3匹 | J6: 1 | K6: =VLOOKUP(H6,室内机清单!A:E,3,FALSE) -> 8 | L6: =K6*J6 -> 8 | M6: =(L6+L7)*1000/D6 -> 227.27273 | N6: =VLOOKUP(H6,室内机清单!A:E,5,FALSE) -> 无 | O6: 领航者IV MJV-200W-E01-LHIV 制冷量：20kW 制热量：22.9kW 匹数：大7匹 | P6: =L10/T6 -> 0.905 | Q6: 领航者Ⅲ | R6: 超薄轻音室内机Pro | S6: MJV-200W-E01-LHⅢ | T6: =IF(S6="","",VLOOKUP(S6,室外机清单!$B$1:$E$219,2,FALSE)) -> 20 | U6: =IF(S6="","",VLOOKUP(S6,室外机清单!$B$1:$E$219,3,FALSE)) -> 22.9 | V6: =IF(S6="","",VLOOKUP(S6,室外机清单!$B$1:$E$219,4,FALSE)) -> 大7
B7: 2 | D7: 27 | E7: 200 | F7: =(D7*E7)/1000 -> 5.4 | G7: =R7 -> 超薄轻音室内机Pro | H7: MJV-45T2/X-TS | I7: =VLOOKUP(H7,室内机清单!A:E,4,FALSE) -> 小2匹 | J7: 1 | K7: =VLOOKUP(H7,室内机清单!A:E,3,FALSE) -> 4.5 | L7: =K7*J7 -> 4.5 | M7: =L7*1000/D7 -> 166.66667 | N7: =VLOOKUP(H7,室内机清单!A:E,5,FALSE) -> 无 | R7: 超薄轻音室内机Pro
B8: 4 | C8: 次卧1 | D8: 13 | E8: 200 | F8: =(D8*E8)/1000 -> 2.6 | G8: =R8 -> 超薄轻音室内机Pro | H8: MJV-28T2/X-TS | I8: =VLOOKUP(H8,室内机清单!A:E,4,FALSE) -> 1匹 | J8: 1 | K8: =VLOOKUP(H8,室内机清单!A:E,3,FALSE) -> 2.8 | L8: =K8*J8 -> 2.8 | M8: =L8*1000/D8 -> 215.38462 | N8: =VLOOKUP(H8,室内机清单!A:E,5,FALSE) -> 无 | R8: 超薄轻音室内机Pro
B9: 5 | C9: 次卧2 | D9: 13 | E9: 200 | F9: =(D9*E9)/1000 -> 2.6 | G9: =R9 -> 超薄轻音室内机Pro | H9: MJV-28T2/X-TS | I9: =VLOOKUP(H9,室内机清单!A:E,4,FALSE) -> 1匹 | J9: 1 | K9: =VLOOKUP(H9,室内机清单!A:E,3,FALSE) -> 2.8 | L9: =K9*J9 -> 2.8 | M9: =L9*1000/D9 -> 215.38462 | N9: =VLOOKUP(H9,室内机清单!A:E,5,FALSE) -> 无 | R9: 超薄轻音室内机Pro
A10: 小计 | J10: =SUM(J6:J9) -> 4 | K10: - | L10: =SUM(L6:L9) -> 18.1 | M10: - | N10: -
A11: 设计特别说明：
A12: ﹡为保证制冷使用效果，项目制冷区域的单位面积冷量配置值由专业暖通设计工程师综合各冷负荷影响因素后核算所得。 ﹡配置表为初步设计选型方案，未考虑到现场情况及材料等实际情况，具体施工可根据实际情况进行调整。 ﹡如客户指定的冷量配置不满足设计冷量配置指标，需提前跟客户明确预计使用效果。 ﹡以上数据根据国标《民用建筑供暖通风与空气调节设计规范》GB50736-2012。
A16: 二、设备报价
A17: 序号 | B17: 设备名称 | F17: 型号 | H17: 单位 | I17: 数量 | J17: 单价（元） | L17: 总价（元） | N17: 备注
A18: =COUNTA($B$18) -> 1 | B18: 多联室外机 | F18: MJV-180W-E01-LHIV | H18: 台 | I18: 1 | J18: 13674 | L18: =I18*J18 -> 13674 | N18: 220V
A19: =COUNTA($B$18:B19) -> 2 | B19: 超薄轻音室内机Pro | F19: MJV-28T2/X-TS | H19: 台 | I19: 2 | J19: 1754.73 | L19: =I19*J19 -> 3509.46 | N19: 标配线控器
A20: =COUNTA($B$18:B20) -> 3 | B20: 超薄轻音室内机Pro | F20: MJV-56T2/X-TS | H20: 台 | I20: 1 | J20: 2024.23 | L20: =I20*J20 -> 2024.23 | N20: 标配线控器
A21: =COUNTA($B$18:B21) -> 4 | B21: 超薄轻音室内机Pro | F21: MJV-80T2/X-TS | H21: 台 | I21: 1 | J21: 2601.73 | L21: =I21*J21 -> 2601.73 | N21: 标配线控器
A22: =COUNTA($B$18:B22) -> 5 | B22: 二、设备小计（元） | L22: =SUM(L18:M21) -> 21809.42
A23: 三、材料及安装报价
A24: 序号 | B24: 名称 | E24: 规格 | H24: 单位 | I24: 数量 | J24: 单价（元） | L24: 总价（元） | N24: 备注
A25: 1 | B25: 材料及安装费 | E25: 安装人工费 | H25: 台 | I25: =SUM(I19:I21) -> 4 | J25: 1500 | L25: =I25*J25 -> 6000
A26: 2 | E26: 铜管及橡塑保温套管 | N26: 铜管：海亮/中佳/金龙 水管：中财、联塑 保温棉：金环
A27: 3 | E27: 冷凝水管及橡塑保温套管
A28: 4 | E28: 标准出回风口（带过滤网） | N28: ABS材质、设备标配尺寸
A29: 5 | E29: 信号线 | N29: 国标
A30: 6 | E30: 制冷剂R410A（环保冷媒）
A31: 7 | E31: 外机支架、吊杆、帆布软接等辅材 | N31: 国标
A32: 8 | B32: 三、材料及安装小计（元） | L32: =SUM(L25) -> 6000
A33: 9 | B33: 合计（元） | L33: =L22+L32 -> 27809.42
A34: 备注 | B34: 1、本报价不含复合风管费用，不含加长风口费用。
B35: 2、本报价不含线控器管线开槽及预埋86底盒费用（由甲方负责）。
B36: 3、本报价多联机限定主铜管≤10米，支铜管≤7米，多台内机累计，超出部分额外收取费用。
B37: 4、本报价不包含空调电源线，由甲方负责接至空调设备位置，并在电箱预留空气开关。
B38: 5、本报价不含税。
B39: 6、本报价有效期为1个月。
D41: 数量 | E41: 型号 | H41: 价格
A42: 1 | C42: 主卧风管机 | D42: 1 | E42: 大三匹双出风KFR-75T2W/B3-SSA(1)IV | H42: 6300 | I42: 此报价包含7米铜管1.6米进风口和回风口加铁架
M45: 合计34109

Sheet 新风设备表
A1: 名称 | B1: 型号 | C1: 风量 | F1: 水力模块搭配关系
A2: 全热交换器 | B2: MQXF250 | C2: 250 | G2: 主机型号 | H2: 水力模块型号1 | I2: 水力模块型号1
A3: 全热交换器 | B3: MQXF350 | C3: 350 | F3: 领航者Ⅱ系列室外机 | G3: MJV-280W/S-X8-LHII | H3: SFEN-280/N1X-A
A4: 全热交换器 | B4: MQXF250II | C4: 250 | F4: 领航者Ⅱ系列室外机 | G4: MJV-335W/S-X8-LHII | H4: SFEN-280/N1X-A
A5: 全热交换器 | B5: MQXF350II | C5: 350 | F5: 领航者Ⅲ系列室外机 | G5: MJV-120W-E01-LHⅢ | H5: SFEN-180/N1X-A | I5: SFEN-180/N1X-BⅡ
A6: 单向流新风机 | B6: MDXF200 | C6: 200 | F6: 领航者Ⅲ系列室外机 | G6: MJV-140W-E01-LHⅢ | H6: SFEN-180/N1X-A | I6: SFEN-180/N1X-BⅡ
A7: 单向流新风机 | B7: MDXF200D | C7: 200 | F7: 领航者Ⅲ系列室外机 | G7: MJV-160W-E01-LHⅢ | H7: SFEN-180/N1X-A | I7: SFEN-180/N1X-BⅡ
A8: 单向流新风机 | B8: MDXF160G | C8: 160 | F8: 领航者Ⅲ系列室外机 | G8: MJV-180W-E01-LHⅢ | H8: SFEN-180/N1X-A | I8: SFEN-180/N1X-BⅡ
A9: X新风系列全热交换器 | B9: MQXF250M | C9: 250 | F9: 领航者Ⅲ系列室外机 | G9: MJV-200W-E01-LHⅢ | H9: SFEN-180/N1X-A | I9: SFEN-180/N1X-BⅡ
A10: X新风系列全热交换器 | B10: MQXF350M | C10: 350 | F10: 领航者Ⅲ系列室外机 | G10: MJV-200W/S-E01-LHⅢ | H10: SFEN-180/N1X-A | I10: SFEN-180/N1X-BⅡ
F11: 领航者Ⅲ系列室外机 | G11: MJV-224W-E01-LHⅢ | H11: SFEN-180/N1X-A | I11: SFEN-180/N1X-BⅡ
F12: 领航者Ⅲ系列室外机 | G12: MJV-224W/S-E01-LHⅢ | H12: SFEN-180/N1X-A | I12: SFEN-180/N1X-BⅡ
B13: 全热交换器 | C13: 单向流新风机 | D13: X新风系列全热交换器 | F13: 探索家室外机 | G13: MJV-120W-E01-TS | H13: SFEN-180/N1X-A | I13: SFEN-180/N1X-BⅡ
B14: MQXF250 | C14: MDXF200 | D14: MQXF250M | F14: 探索家室外机 | G14: MJV-140W-E01-TS | H14: SFEN-180/N1X-A | I14: SFEN-180/N1X-BⅡ
B15: MQXF350 | C15: MDXF200D | D15: MQXF350M | F15: 探索家室外机 | G15: MJV-160W-E01-TS | H15: SFEN-180/N1X-A | I15: SFEN-180/N1X-BⅡ
B16: MQXF250II | C16: MDXF160G | F16: 探索家室外机 | G16: MJV-180W-E01-TS | H16: SFEN-180/N1X-A | I16: SFEN-180/N1X-BⅡ
B17: MQXF350II | F17: 设计家系列室外机 | G17: MJV-120W/B-E01-SJ | H17: SFEN-180/N1X-A | I17: SFEN-180/N1X-BⅡ
F18: 设计家系列室外机 | G18: MJV-140W/B-E01-SJ | H18: SFEN-180/N1X-A | I18: SFEN-180/N1X-BⅡ
F19: 设计家系列室外机 | G19: MJV-160W/B-E01-SJ | H19: SFEN-180/N1X-A | I19: SFEN-180/N1X-BⅡ
D20: ≥50L | F20: 设计家系列室外机 | G20: MJV-180W/B-E01-SJ | H20: SFEN-180/N1X-A | I20: SFEN-180/N1X-BⅡ
D21: ≥60L | F21: 设计家系列室外机 | G21: MJV-200W-E01-SJ | H21: SFEN-180/N1X-A | I21: SFEN-180/N1X-BⅡ
D22: ≥80L | F22: 设计家系列室外机 | G22: MJV-224W-E01-SJ | H22: SFEN-180/N1X-A | I22: SFEN-180/N1X-BⅡ
F23: 设计家II系列室外机 | G23: MJV-120W-E01-SJⅡ | H23: SFEN-180/N1X-A | I23: SFEN-180/N1X-BⅡ
A24: 水力模块型号 | B24: SFEN-180/N1X-A | C24: SFEN-180/N1X-BⅡ | D24: SFEN-280/N1X-A | F24: 设计家II系列室外机 | G24: MJV-140W-E01-SJⅡ | H24: SFEN-180/N1X-A | I24: SFEN-180/N1X-BⅡ
A25: 水泵参数 | B25: 流量:3m³/h 扬程:5.2m | C25: 流量:3m³/h 扬程:5.2m | D25: 流量:4.8m³/h 扬程:11m | F25: 设计家II系列室外机 | G25: MJV-160W-E01-SJⅡ | H25: SFEN-180/N1X-A | I25: SFEN-180/N1X-BⅡ
F26: 设计家II系列室外机 | G26: MJV-180W-E01-SJⅡ | H26: SFEN-180/N1X-A | I26: SFEN-180/N1X-BⅡ
F27: 设计家II系列室外机 | G27: MJV-200W-E01-SJⅡ | H27: SFEN-180/N1X-A | I27: SFEN-180/N1X-BⅡ
F28: 设计家II系列室外机 | G28: MJV-224W-E01-SJⅡ | H28: SFEN-180/N1X-A | I28: SFEN-180/N1X-BⅡ

Sheet 名称管理器
A1: 系列名称 | B1: 领航者Ⅲ | C1: 领航者Ⅱ | D1: 领航者Ⅳ | E1: 设计家Ⅱ | F1: 空气梦想家Ⅱ | G1: 探索家 | H1: 星光pro | I1: 智慧家 | J1: 美家 | K1: 理想家III | L1: 理想家IV | M1: 星光 | N1: 设计家青春版 | O1: 玲珑II | P1: GC | Q1: 雅境 | R1: MDSIII
A2: 对应室内机 | B2: 超薄轻音室内机 | C2: 超薄轻音室内机 | D2: 超薄轻音室内机 | E2: 设计家除醛室内机 | F2: 空气梦想家Ⅱ室内机 | G2: 新风内机 | H2: 超薄轻音室内机 | I2: 超薄轻音室内机 | J2: 美家BE离子云Plus内机 | K2: 超薄轻音室内机 | L2: 超薄轻音室内机 | M2: TY通用内机 | N2: TY通用内机 | O2: 厨房式室内机 | P2: GC系列客卧式室内机 | Q2: 雅境系列室内机 | R2: 玲珑客卧式室内机
B3: 领航者除菌室内机 | C3: 领航者除菌室内机 | D3: 超薄轻音室内机Pro | E3: 厨房式室内机 | F3: 厨房式室内机 | G3: 超薄轻音室内机 | H3: 厨清凉室内机 | I3: 厨房式室内机 | J3: 超薄轻音室内机 | K3: 厨房式室内机 | L3: 厨房式室内机 | M3: 厨房式室内机 | N3: 厨房式室内机 | O3: TY通用内机 | P3: 厨房式室内机 | Q3: TY通用内机 | R3: TY通用内机
B4: 厨房式室内机 | C4: 厨房式室内机 | D4: 领航者除菌室内机 | E4: 厨清凉室内机 | F4: 厨清凉室内机 | G4: 超薄轻音室内机Pro | H4: 卫浴空调室内机 | I4: 新风内机 | J4: 厨房式室内机 | K4: 新风内机 | L4: 新风内机 | M4: 玲珑客卧式室内机 | N4: 厨清凉室内机 | O4: 厨清凉室内机 | Q4: 厨房式室内机 | R4: 厨房式室内机
B5: 厨清凉室内机 | C5: 厨清凉室内机 | D5: 厨房式室内机 | E5: 新风内机 | F5: 超薄轻音室内机 | G5: 领航者除菌室内机 | H5: 超薄轻音室内机Pro | I5: 厨清凉室内机 | J5: 新风内机 | K5: 厨清凉室内机 | L5: 厨清凉室内机 | M5: 厨清凉室内机 | N5: 卫浴空调室内机 | O5: 卫浴空调室内机
B6: 新风内机 | C6: 新风内机 | D6: 厨清凉室内机 | E6: 超薄轻音室内机 | F6: 卫浴空调室内机 | G6: 设计家除醛室内机 | H6: 冷暖双舒适内机 | I6: 卫浴空调室内机 | J6: 厨清凉室内机 | K6: 卫浴空调室内机 | L6: 卫浴空调室内机 | M6: 卫浴空调室内机
B7: 卫浴空调室内机 | C7: 卫浴空调室内机 | D7: 新风内机 | E7: 卫浴空调室内机 | F7: 超薄轻音室内机Pro | G7: 冷暖双舒适内机 | H7: 厨房式室内机 | I7: 超薄轻音室内机Pro | J7: 卫浴空调室内机 | K7: 超薄轻音室内机Pro | L7: 超薄轻音室内机Pro
B8: 超薄轻音室内机Pro | C8: 超薄轻音室内机Pro | D8: 卫浴空调室内机 | E8: 超薄轻音室内机Pro | F8: 冷暖双舒适内机 | G8: 空气梦想家Ⅱ室内机 | I8: 冷暖双舒适内机 | J8: 超薄轻音室内机Pro | K8: 冷暖双舒适内机 | L8: 冷暖双舒适内机
B9: 冷暖双舒适内机 | C9: 冷暖双舒适内机 | D9: 冷暖双舒适内机 | E9: 冷暖双舒适内机 | G9: 厨清凉室内机 | I9: 美家BE离子云Plus内机 | J9: 冷暖双舒适内机 | K9: 空气梦想家Ⅱ室内机 | L9: 空气梦想家Ⅱ室内机
B10: 空气梦想家Ⅱ室内机 | C10: 空气梦想家Ⅱ室内机 | D10: 空气梦想家Ⅱ室内机 | G10: 厨房式室内机
D11: 美家BE离子云Plus内机 | G11: 卫浴空调室内机
A14: 室内机名称 | B14: 超薄轻音室内机 | C14: 超薄轻音室内机Pro | D14: 冷暖双舒适内机 | E14: 领航者除菌室内机 | F14: 新风内机 | G14: 设计家除醛室内机 | H14: 设计家客卧式室内机 | I14: 厨清凉室内机 | J14: 前装系列小多联 | K14: GC系列客卧式室内机 | L14: 厨房式室内机 | M14: 空气梦想家室内机 | N14: 雅境系列室内机 | O14: TY通用内机 | P14: 星光pro系列客卧内机 | Q14: 空气梦想家Ⅱ室内机 | R14: 美家BE离子云Plus内机 | S14: 卫浴空调室内机
A15: 室内机型号 | B15: MJV-22T2-TS | C15: MJV-22T2/PX-TS | D15: MJV-22T2/P-SS | E15: MJV-22T2/P-LH | F15: MJV-22T2/P-XF | G15: MJV-22T2/P-SJ | H15: MJV-22T2/X-SJ | I15: MJV-36Q/P-TC | J15: MDVH-22T2/DN1-Z | K15: MJV-22T2/DX-GC | L15: MDVH-32T2/N1-K | M15: MJV-22T2/X-MX | N15: MJV-22T2/DX-YJ | O15: MJV-22T2/DX-TY | P15: MDS-22T2-XGpro | Q15: MJV-22T2-MXⅡ | R15: MJV-22T2/X-MZ | S15: MJV-28Q/P-TY
B16: MJV-28T2-TS | C16: MJV-28T2/PX-TS | D16: MJV-28T2/P-SS | E16: MJV-28T2/P-LH | F16: MJV-28T2/P-XF | G16: MJV-28T2/P-SJ | H16: MJV-28T2/X-SJ | J16: MDVH-28T2/DN1-Z | K16: MJV-28T2/DX-GC | M16: MJV-28T2/X-MX | N16: MJV-28T2/DX-YJ | O16: MJV-28T2/DX-TY | P16: MDS-28T2-XGpro | Q16: MJV-28T2-MXⅡ | R16: MJV-28T2/X-MZ
B17: MJV-36T2-TS | C17: MJV-36T2/PX-TS | D17: MJV-36T2/P-SS | E17: MJV-36T2/P-LH | F17: MJV-36T2/P-XF | G17: MJV-36T2/P-SJ | H17: MJV-36T2/X-SJ | J17: MDVH-36T2/DN1-Z | K17: MJV-36T2/DX-GC | M17: MJV-36T2/X-MX | N17: MJV-36T2/DX-YJ | O17: MJV-36T2/DX-TY | P17: MDS-36T2-XGpro | Q17: MJV-36T2-MXⅡ | R17: MJV-36T2/X-MZ
B18: MJV-45T2-TS | C18: MJV-45T2/PX-TS | D18: MJV-42T2/P-SS | E18: MJV-45T2/P-LH | F18: MJV-45T2/P-XF | G18: MJV-45T2/P-SJ | H18: MJV-45T2/X-SJ | J18: MDVH-45T2/DN1-Z | K18: MJV-45T2/DX-GC | M18: MJV-45T2/X-MX | N18: MJV-45T2/DX-YJ | O18: MJV-45T2/DX-TY | P18: MDS-45T2-XGpro | Q18: MJV-45T2-MXⅡ | R18: MJV-45T2/X-MZ
B19: MJV-56T2-TS | C19: MJV-56T2/PX-TS | D19: MJV-71T2/P-SS | E19: MJV-56T2/P-LH | F19: MJV-56T2/P-XF | G19: MJV-56T2/P-SJ | H19: MJV-56T2/X-SJ | J19: MDVH-56T2/DN1-Z | K19: MJV-56T2/DX-GC | M19: MJV-56T2/X-MX | N19: MJV-56T2/DX-YJ | O19: MJV-56T2/DX-TY | P19: MDS-56T2-XGpro | Q19: MJV-56T2-MXⅡ | R19: MJV-56T2/X-MZ
B20: MJV-71T2-TS | C20: MJV-71T2/PX-TS | D20: MJV-80T2/P-SS | E20: MJV-71T2/P-LH | F20: MJV-71T2/P-XF | G20: MJV-71T2/P-SJ | H20: MJV-71T2/X-SJ | J20: MDVH-71T2/DN1-Z | K20: MJV-71T2/DX-GC | M20: MJV-71T2/X-MX | N20: MJV-71T2/DX-YJ | O20: MJV-71T2/DX-TY | P20: MDS-71T2-XGpro | Q20: MJV-71T2-MXⅡ | R20: MJV-71T2/X-MZ
B21: MJV-80T2-TS | C21: MJV-80T2/PX-TS | E21: MJV-80T2/P-LH | F21: MJV-80T2/P-XF | G21: MJV-80T2/P-SJ | H21: MJV-22T2/PX-SJ | K21: MJV-22T2/DPX-GC | O21: MJV-80T2/DX-TY | P21: MDS-22T2/P-XGpro
B22: MJV-22T2/P-TS | C22: MJV-22T2/X-TS | G22: MJV-22T2-SJ | H22: MJV-28T2/PX-SJ | K22: MJV-28T2/DPX-GC | P22: MDS-28T2/P-XGpro
B23: MJV-28T2/P-TS | C23: MJV-28T2/X-TS | G23: MJV-28T2-SJ | H23: MJV-36T2/PX-SJ | K23: MJV-36T2/DPX-GC | P23: MDS-36T2/P-XGpro
B24: MJV-36T2/P-TS | C24: MJV-36T2/X-TS | G24: MJV-36T2-SJ | H24: MJV-45T2/PX-SJ | K24: MJV-45T2/DPX-GC | P24: MDS-45T2/P-XGpro
B25: MJV-45T2/P-TS | C25: MJV-45T2/X-TS | G25: MJV-45T2-SJ | H25: MJV-56T2/PX-SJ | K25: MJV-56T2/DPX-GC | P25: MDS-56T2/P-XGpro
B26: MJV-56T2/P-TS | C26: MJV-56T2/X-TS | G26: MJV-56T2-SJ | H26: MJV-71T2/PX-SJ | K26: MJV-71T2/DPX-GC | P26: MDS-71T2/P-XGpro
B27: MJV-71T2/P-TS | C27: MJV-71T2/X-TS | G27: MJV-71T2-SJ | K27: MJV-22T2/PX-GC
B28: MJV-80T2/P-TS | C28: MJV-80T2/X-TS | K28: MJV-28T2/PX-GC
K29: MJV-36T2/PX-GC
K30: MJV-45T2/PX-GC
K31: MJV-56T2/PX-GC
K32: MJV-71T2/PX-GC
K33: MJV-80T2/PX-GC
B36: 全热交换器
B37: 单向流新风机
B38: X新风系列全热交换器
M40: 领航者Ⅳ系列室外机
A45: 室外机名称 | B45: 智慧家系列室外机 | C45: 美家系列室外机 | D45: 设计家系列室外机 | E45: 设计家Ⅱ系列室外机 | F45: 领航者Ⅳ系列室外机 | G45: 领航者Ⅲ系列室外机 | H45: 领航者Ⅱ系列室外机 | I45: 理想家III系列室外机 | J45: 理想家IV系列室外机 | K45: 玲珑II系列室外机 | L45: MDSIII系列室外机 | M45: GC系列室外机 | N45: 空气梦想家Ⅱ系列室外机 | O45: 雅境系列室外机 | P45: 设计家青春版系列室外机 | Q45: 星光系列室外机 | R45: 星光pro系列室外机 | S45: 探索家系列室外机
A46: 室外机型号 | B46: MJV-120W-E01-MZ | C46: MJV-120W-E01-MZ | D46: MJV-120W/B-E01-SJ | E46: MJV-120W-E01-SJⅡ | F46: MJV-125W-E01-LHⅣ | G46: MJV-120W-E01-LHⅢ | H46: MJV-280W/S-X8-LHII | I46: MJV-120W-E01-LXIII | J46: MJV-125W-X6-LXⅣ | K46: MJV-80W-X4-LLⅡA | L46: MDS-H100W-A(1) Ⅲ | M46: MJV-80W-D01-GC | N46: MJV-120W-E01-MXⅡ | O46: MJV-100W-D01-YJ | P46: MJV-120W-E01-SJQC | Q46: MDS-80W-X4-XG | R46: MDS-120W-E01-XGpro | S46: MJV-120W-E01-TS
B47: MJV-140W-E01-MZ | C47: MJV-140W-E01-MZ | D47: MJV-140W/B-E01-SJ | E47: MJV-140W-E01-SJⅡ | F47: MJV-140W-E01-LHⅣ | G47: MJV-140W-E01-LHⅢ | H47: MJV-335W/S-X8-LHII | I47: MJV-140W-E01-LXIII | J47: MJV-140W-X6-LXⅣ | K47: MJV-100W-D02-LLⅡA | L47: MDS-H120W-A(1) Ⅲ | M47: MJV-100W-D01-GC | N47: MJV-140W-E01-MXⅡ | O47: MJV-120W-D01-YJ | P47: MJV-140W-E01-SJQC | Q47: MDS-100W-D02-XG | R47: MDS-140W-E01-XGpro | S47: MJV-140W-E01-TS
B48: MJV-160W-E01-MZ | C48: MJV-160W-E01-MZ | D48: MJV-160W/B-E01-SJ | E48: MJV-160W-E01-SJⅡ | F48: MJV-160W-E01-LHⅣ | G48: MJV-160W-E01-LHⅢ | I48: MJV-160W-E01-LXIII | K48: MJV-120W-D02-LLⅡA | L48: MDS-H140W-A(1) Ⅲ | M48: MJV-120W-D01-GC | N48: MJV-160W-E01-MXⅡ | O48: MJV-140W-D01-YJ | P48: MJV-160W-E01-SJQC | Q48: MDS-120W-D02-XG | R48: MDS-160W-E01-XGpro | S48: MJV-160W-E01-TS
B49: MJV-180W-E01-MZ | C49: MJV-180W-E01-MZ | D49: MJV-180W/B-E01-SJ | E49: MJV-180W-E01-SJⅡ | F49: MJV-180W-E01-LHⅣ | G49: MJV-180W-E01-LHⅢ | I49: MJV-180W-E01-LXIII | K49: MJV-140W-D02-LLⅡA | L49: MDS-160W-X6-(1)Ⅲ | M49: MJV-140W-D01-GC | N49: MJV-180W-E01-MXⅡ | O49: MJV-140W-E01-YJ | P49: MJV-180W-E01-SJQC | Q49: MDS-140W-D02-XG | R49: MDS-180W-E01-XGpro | S49: MJV-180W-E01-TS
...

Sheet 室内机清单
A1: 型号 | B1: 内机形式 | C1: 制冷量 | D1: 匹数 | E1: 冷凝提升泵
A2: MJV-22T2/P-XF | B2: 新风内机 | C2: 2.2 | D2: 小1匹 | E2: 有 | H2: 2200 | I2: 2500
A3: MJV-28T2/P-XF | B3: 新风内机 | C3: 2.8 | D3: 1匹 | E3: 有 | H3: 2800 | I3: 3200
A4: MJV-36T2/P-XF | B4: 新风内机 | C4: 3.6 | D4: 1.5匹 | E4: 有 | H4: 3600 | I4: 4000
A5: MJV-45T2/P-XF | B5: 新风内机 | C5: 4.5 | D5: 小2匹 | E5: 有 | H5: 4500 | I5: 5000
A6: MJV-56T2/P-XF | B6: 新风内机 | C6: 5.6 | D6: 2匹 | E6: 有 | H6: 5600 | I6: 6300
A7: MJV-71T2/P-XF | B7: 新风内机 | C7: 7.1 | D7: 3匹 | E7: 有 | H7: 7100 | I7: 8000
A8: MJV-80T2/P-XF | B8: 新风内机 | C8: 8 | D8: 大3匹 | E8: 有 | H8: 8000 | I8: 9000
A9: MJV-22T2/P-SS | B9: 冷暖双舒适内机 | C9: 2.2 | D9: 小1匹 | E9: 有 | K9: 2200 | L9: 2500
A10: MJV-28T2/P-SS | B10: 冷暖双舒适内机 | C10: 2.8 | D10: 1匹 | E10: 有 | K10: 2800 | L10: 3200
A11: MJV-36T2/P-SS | B11: 冷暖双舒适内机 | C11: 3.6 | D11: 1.5匹 | E11: 有 | K11: 3600 | L11: 4000
A12: MJV-42T2/P-SS | B12: 冷暖双舒适内机 | C12: 4.2 | D12: 小2匹 | E12: 有 | K12: 4200 | L12: 4800
A13: MJV-56T2/P-SS | B13: 冷暖双舒适内机 | D13: =C13/2.5 -> 0 | E13: 有 | K13: 7100 | L13: 8000
A14: MJV-71T2/P-SS | B14: 冷暖双舒适内机 | C14: 7.1 | D14: 3匹 | E14: 有 | K14: 8000 | L14: 9000
A15: MJV-80T2/P-SS | B15: 冷暖双舒适内机 | C15: 8 | D15: 大3匹 | E15: 有
A16: MJV-22T2-TS | B16: 超薄轻音室内机 | C16: 2.2 | D16: 小1匹 | E16: 无 | H16: MJV-22T2-TS
A17: MJV-28T2-TS | B17: 超薄轻音室内机 | C17: 2.8 | D17: 1匹 | E17: 无 | H17: MJV-28T2-TS
A18: MJV-36T2-TS | B18: 超薄轻音室内机 | C18: 3.6 | D18: 1.5匹 | E18: 无 | H18: MJV-36T2-TS
A19: MJV-45T2-TS | B19: 超薄轻音室内机 | C19: 4.5 | D19: 小2匹 | E19: 无 | H19: MJV-45T2-TS
A20: MJV-56T2-TS | B20: 超薄轻音室内机 | C20: 5.6 | D20: 2匹 | E20: 无 | H20: MJV-56T2-TS
A21: MJV-71T2-TS | B21: 超薄轻音室内机 | C21: 7.1 | D21: 3匹 | E21: 无 | H21: MJV-71T2-TS
A22: MJV-80T2-TS | B22: 超薄轻音室内机 | C22: 8 | D22: 大3匹 | E22: 无 | H22: MJV-80T2-TS
A23: MJV-22T2/P-TS | B23: 超薄轻音室内机 | C23: 2.2 | D23: 小1匹 | E23: 有 | H23: MJV-22T2/P-TS
A24: MJV-28T2/P-TS | B24: 超薄轻音室内机 | C24: 2.8 | D24: 1匹 | E24: 有 | H24: MJV-28T2/P-TS
A25: MJV-36T2/P-TS | B25: 超薄轻音室内机 | C25: 3.6 | D25: 1.5匹 | E25: 有 | H25: MJV-36T2/P-TS
A26: MJV-45T2/P-TS | B26: 超薄轻音室内机 | C26: 4.5 | D26: 小2匹 | E26: 有 | H26: MJV-45T2/P-TS
A27: MJV-56T2/P-TS | B27: 超薄轻音室内机 | C27: 5.6 | D27: 2匹 | E27: 有 | H27: MJV-56T2/P-TS
... A29: MJV-80T2/P-TS | B29: 超薄轻音室内机 | C29: 8 | D29: 大3匹 | E29: 有 | H29: MJV-80T2/P-TS
A30: MJV-22T2/PX-TS | B30: 超薄轻音室内机Pro | C30: 2.2 | D30: 小1匹 | E30: 有
A31: MJV-28T2/PX-TS | B31: 超薄轻音室内机Pro | C31: 2.8 | D31: 1匹 | E31: 有
A32: MJV-36T2/PX-TS | B32: 超薄轻音室内机Pro | C32: 3.6 | D32: 1.5匹 | E32: 有
A33: MJV-45T2/PX-TS | B33: 超薄轻音室内机Pro | C33: 4.5 | D33: 小2匹 | E33: 有
A34: MJV-56T2/PX-TS | B34: 超薄轻音室内机Pro | C34: 5.6 | D34: 2匹 | E34: 有
A35: MJV-71T2/PX-TS | B35: 超薄轻音室内机Pro | C35: 7.1 | D35: 3匹 | E35: 有
A36: MJV-80T2/PX-TS | B36: 超薄轻音室内机Pro | C36: 8 | D36: 大3匹 | E36: 有
A37: MJV-22T2/X-TS | B37: 超薄轻音室内机Pro | C37: 2.2 | D37: 小1匹 | E37: 无
A38: MJV-28T2/X-TS | B38: 超薄轻音室内机Pro | C38: 2.8 | D38: 1匹 | E38: 无
A39: MJV-36T2/X-TS | B39: 超薄轻音室内机Pro | C39: 3.6 | D39: 1.5匹 | E39: 无
A40: MJV-45T2/X-TS | B40: 超薄轻音室内机Pro | C40: 4.5 | D40: 小2匹 | E40: 无
A41: MJV-56T2/X-TS | B41: 超薄轻音室内机Pro | C41: 5.6 | D41: 2匹 | E41: 无
...

Sheet 室外机清单
A1: 系列 | B1: 型号 | C1: 制冷量 | D1: 制热量 | E1: 匹数 | F1: 水力模块型号
A2: 领航者Ⅱ系列室外机 | B2: MDVH-V120W/N1-E01LH(E1)Ⅱ | C2: 12 | D2: 14 | E2: 5
A3: 领航者Ⅱ系列室外机 | B3: MDVH-V140W/N1-E01LH(E1)Ⅱ | C3: 14 | D3: 16 | E3: 6
A4: 领航者Ⅱ系列室外机 | B4: MDVH-V160W/N1-E01LH(E1)Ⅱ | C4: 16 | D4: 18.5 | E4: 大6
A5: 领航者Ⅱ系列室外机 | B5: MDVH-V180W/N1-E01LH(E1)Ⅱ | C5: 18 | D5: 20 | E5: 7
A6: 领航者Ⅱ系列室外机 | B6: MJV-200W-E01-LHⅡ | C6: 20 | D6: 22.4 | E6: 大7
A7: 领航者Ⅱ系列室外机 | B7: MJV-224W-E01-LHⅡ | C7: 22.4 | D7: 25 | E7: 8
A8: 领航者Ⅱ系列室外机 | B8: MJV-200W/S-E01-LHⅡ | C8: 20 | D8: 22.4 | E8: 大7
A9: 领航者Ⅱ系列室外机 | B9: MJV-224W/S-E01-LHⅡ | C9: 22.4 | D9: 25 | E9: 8
A10: 领航者Ⅱ系列室外机 | B10: MJV-280W/S-X8-LHII | C10: 28.5 | D10: 31.5 | E10: 10
A11: 领航者Ⅱ系列室外机 | B11: MJV-335W/S-X8-LHII | C11: 33.5 | D11: 37.5 | E11: 12
A12: 领航者Ⅲ系列室外机 | B12: MJV-120W-E01-LHⅢ | C12: 12 | D12: 14.5 | E12: 5
A13: 领航者Ⅲ系列室外机 | B13: MJV-140W-E01-LHⅢ | C13: 14 | D13: 16.5 | E13: 6
A14: 领航者Ⅲ系列室外机 | B14: MJV-160W-E01-LHⅢ | C14: 16 | D14: 19 | E14: 大6
A15: 领航者Ⅲ系列室外机 | B15: MJV-180W-E01-LHⅢ | C15: 18 | D15: 20.5 | E15: 7
A16: 领航者Ⅲ系列室外机 | B16: MJV-200W-E01-LHⅢ | C16: 20 | D16: 22.9 | E16: 大7
A17: 领航者Ⅲ系列室外机 | B17: MJV-200W/S-E01-LHⅢ | C17: 20 | D17: 22.9 | E17: 大7
A18: 领航者Ⅲ系列室外机 | B18: MJV-224W-E01-LHⅢ | C18: 22.4 | D18: 25.5 | E18: 8
A19: 领航者Ⅲ系列室外机 | B19: MJV-224W/S-E01-LHⅢ | C19: 22.4 | D19: 25.5 | E19: 8
A20: 领航者Ⅳ系列室外机 | B20: MJV-125W-E01-LHⅣ | C20: 12.5 | D20: 14.5 | E20: 5 | H20: 12500 | I20: 14500
A21: 领航者Ⅳ系列室外机 | B21: MJV-140W-E01-LHⅣ | C21: 14 | D21: 16.5 | E21: 6 | H21: 14000 | I21: 16500
A22: 领航者Ⅳ系列室外机 | B22: MJV-160W-E01-LHⅣ | C22: 16 | D22: 19 | E22: 大6 | H22: 16000 | I22: 19000
A23: 领航者Ⅳ系列室外机 | B23: MJV-180W-E01-LHⅣ | C23: 18 | D23: 20.5 | E23: 7 | H23: 18000 | I23: 20500
A24: 设计家系列室外机 | B24: MJV-120W/B-E01-SJ | C24: 12 | D24: 14 | E24: 5
A25: 设计家系列室外机 | B25: MJV-140W/B-E01-SJ | C25: 14 | D25: 16 | E25: 6
A26: 设计家系列室外机 | B26: MJV-160W/B-E01-SJ | C26: 16 | D26: 18.5 | E26: 大6
A27: 设计家系列室外机 | B27: MJV-180W/B-E01-SJ | C27: 18 | D27: 20 | E27: 7
A28: 设计家系列室外机 | B28: MJV-200W-E01-SJ | C28: 20 | D28: 22.4 | E28: 大7
A29: 设计家系列室外机 | B29: MJV-224W-E01-SJ | C29: 22.4 | D29: 25 | E29: 8
A30: 设计家II系列室外机 | B30: MJV-120W-E01-SJⅡ | C30: 12 | D30: 14 | E30: 5
A31: 设计家II系列室外机 | B31: MJV-140W-E01-SJⅡ | C31: 14 | D31: 16 | E31: 6
A32: 设计家II系列室外机 | B32: MJV-160W-E01-SJⅡ | C32: 16 | D32: 18.5 | E32: 大6
A33: 设计家II系列室外机 | B33: MJV-180W-E01-SJⅡ | C33: 18 | D33: 20 | E33: 7
A34: 设计家II系列室外机 | B34: MJV-200W-E01-SJⅡ | C34: 20 | D34: 22.9 | E34: 大7
A35: 设计家II系列室外机 | B35: MJV-224W-E01-SJⅡ | C35: 22.4 | D35: 25.5 | E35: 8
A36: 设计家青春版系列室外机 | B36: MJV-120W-E01-SJQC | C36: 12 | D36: 14 | E36: 5
A37: 设计家青春版系列室外机 | B37: MJV-140W-E01-SJQC | C37: 14 | D37: 16.5 | E37: 6
A38: 设计家青春版系列室外机 | B38: MJV-160W-E01-SJQC | C38: 16 | D38: 18.5 | E38: 大6
A39: 设计家青春版系列室外机 | B39: MJV-180W-E01-SJQC | C39: 18 | D39: 20 | E39: 7
A40: 理想家III系列室外机 | B40: MJV-120W-E01-LXIII | C40: 12 | D40: 14.5 | E40: 5
...
